Workbook

Sheet Signage Schedule
A1: 234 CLARKSON AVENUE — DIVISION 10 14 00 SIGNAGE SCHEDULE
A2: Brooklyn, NY 11222
A4: Status Legend:
A6: Name | B6: Description | C6: Qty | D6: Price Each | E6: Extended Price | F6: Status | G6: Basis / Notes
A7: Exterior & Building Identification
A8: Building ID | B8: Exterior building address ID, three individual dimensional numerals reading “234,” mounted at the primary entrance. size/finish assumed to echo the satin-nickel palette used on the interior directory signage (Lobby | Elevator Lobby Signage detail) — 2' cast-metal or high-density-urethane numerals, stud-mounted to the facade, pending an actual exterior sign detail. | C8: 3 | D8: ='Rate Catalog'!H2 -> 100 | E8: =C8*D8 -> 300 | F8: Confirmed
A9: Standpipe / FDC Identification Sign (Assumed) | B9: Approved metal “STANDPIPE” sign at the exterior Siamese fire department connection, per Fire Protection General Note #2. Not in the Durukan Division 10 package — quantity/scope assumed pending confirmation of trade responsibility | C9: 1 | D9: ='Rate Catalog'!H3 -> 25 | E9: =C9*D9 -> 25 | F9: Confirmed
A10: Subtotal — Exterior & Building Identification | E10: =SUM(E8:E9) -> 325
A12: Site & Roadway Signage
A13: ADA Accessible Parking | B13: Accessible/van-accessible parking ID signage at the 1st floor parking area, per ICC/ADA parking signage requirements. Post- vs. wall-mounted condition pending Site/Civil drawings | C13: 1 | D13: ='Rate Catalog'!H11 -> 50 | E13: =C13*D13 -> 50 | F13: Confirmed
A14: Subtotal — Site & Roadway Signage | E14: =SUM(E13:E13) -> 50
A16: Interior Signage
A17: Elevator Evacuation Map | B17: Framed floor-specific evacuation/egress-route graphic posted in each elevator lobby, per NYC fire-safety/evacuation-plan provisions for R-2 occupancies. Not detailed in the Durukan package. | C17: 22 | D17: ='Rate Catalog'!H4 -> 85 | E17: =C17*D17 -> 1870 | F17: Estimated
A18: Elevator Door Jamb Floor ID Sign | B18: Small tactile floor-number tag on the elevator hoistway door jamb at each landing, per ASME A17.1/NYC BC elevator accessibility provisions. Not detailed in the Durukan package. | C18: 22 | D18: ='Rate Catalog'!H5 -> 45 | E18: =C18*D18 -> 990 | F18: Confirmed
A19: Elevator Lobby Floor Directory Signage | B19: Per Durukan “2nd Floor | Elevator Lobby Directory Signage” typical detail: 8" floor number + 1-1/4"/1" directory text + arrows, Octopus Products 28 Satin Nickel metal on black acrylic backing, 4'-6" AFF, at each stair/elevator core per floor. | C19: 23 | D19: ='Rate Catalog'!H6 -> 50 | E19: =C19*D19 -> 1150 | F19: Estimated
A20: Utility & Back-of-House ID Sign (w/ Hazard/Resticted-Access Signage) | B20: Combined room-ID + hazard/restricted-access sign at MEP/back-of-house spaces (Fire Pump Room, Water Room, Electrical Room, Telecom Room, Trash/Refuse Compactor, etc., per Cellar and 1st Floor CAD plans) where the room also warrants an “Authorized Personnel Only” or hazard designation. No dedicated detail sheet in the Durukan package — assumed matte acrylic room-ID sign with integrated pictogram/warning text. | C20: 27 | D20: ='Rate Catalog'!H7 -> 50 | E20: =C20*D20 -> 1350 | F20: Confirmed
A21: Hazard/Restricted Access Signage | B21: Standalone hazard/restricted-access signage (e.g., “Authorized Personnel Only,” electrical hazard) at MEP/back-of-house and roof spaces, separate from the combined Utility & BOH ID sign type above. | C21: 27 | D21: ='Rate Catalog'!H19 -> 30 | E21: =C21*D21 -> 810 | F21: Estimated
A22: Utility & Back-of-House ID Sign | B22: Standard room-ID sign (no hazard designation) at MEP/back-of-house spaces per Cellar through Roof CAD plans. | C22: 26 | D22: ='Rate Catalog'!H12 -> 50 | E22: =C22*D22 -> 1300 | F22: Confirmed
A23: Typical Hallway Directory Signage | B23: Per Durukan “Typical Hallway Directory Signage” detail: unit-range directional plaque w/ arrows, Octopus Products 28 Satin Nickel, 48" AFF, at apartment corridors. | C23: 21 | D23: ='Rate Catalog'!H13 -> 30 | E23: =C23*D23 -> 630 | F23: Estimated
A24: Lobby Floor Indicator Sign | B24: Per Durukan “Lobby | Elevator Lobby Signage” detail: 8" cutout floor number + 1" building/floor text, Octopus Products 28 Satin Nickel on black acrylic backing, 60" AFF, at the ground-floor elevator lobby. | C24: 1 | D24: ='Rate Catalog'!H14 -> 50 | E24: =C24*D24 -> 50 | F24: Estimated
A25: Amenity Room ID Signage | B25: Per Durukan “Amenity Signage” typical detail: icon + 5/8" raised copy + Braille, matte panel, at each named common/amenity room. | C25: 13 | D25: ='Rate Catalog'!H15 -> 50 | E25: =C25*D25 -> 650 | F25: Confirmed
A26: Laundry Signage ("Loads of Fun") | B26: Per Durukan “Laundry Signage” detail: 10" matte white acrylic cutout letters (6' VIF width), 1st floor laundry room. | C26: 1 | D26: ='Rate Catalog'!H16 -> 400 | E26: =C26*D26 -> 400 | F26: Estimated
A27: Co-Working Private Pod Signage | B27: Per Durukan “Co-Working Private Pod Signage” detail: circular wood-tone panel, raised characters + Braille, 48" AFF, POD 1/2/3. | C27: 3 | D27: ='Rate Catalog'!H17 -> 50 | E27: =C27*D27 -> 150 | F27: Estimated
A28: Apartment Entry Signage | B28: Per Durukan “Apartment Entry” detail: raised unit number (2") + Braille, 48" AFF to Braille-plate center, at each apartment entry door. | C28: 98 | D28: ='Rate Catalog'!H18 -> 60 | E28: =C28*D28 -> 5880 | F28: Confirmed
A29: Subtotal — Interior Signage | E29: =SUM(E17:E28) -> 15230
A31: Egress & Life Safety Signage
A32: Illuminated EXIT Signage | B32: Egress path exit signage at each floor. Building height of 105'-0" (Fire Protection titleblock) places this project within NYC high-rise egress-marking thresholds; quantity/distribution assumed to reflect Division 10 photoluminescent (self-luminous, UL924/ASTM E2073) exit signage rather than an electrically-connected fixture. | C32: 79 | D32: ='Rate Catalog'!H8 -> 50 | E32: =C32*D32 -> 3950 | F32: Confirmed
A33: Stairwell Floor-Level ID Plaque | B33: Tactile stairway ID sign at each stair floor landing (floor level, stair designation, roof-access indication) per NYC BC 1022.9-type stairway signage requirements, at all four stairs (A, B, C, D). Not detailed in the Durukan package. | C33: 42 | D33: ='Rate Catalog'!H9 -> 85 | E33: =C33*D33 -> 3570 | F33: Confirmed
A34: Tactile/Braille Stair Door ID | B34: ADA/ICC A117.1 703 tactile + Braille “STAIR” signage at each stair door leaf, at all four stairs. Not detailed in the Durukan package, but follows the same raised-character + Braille standard shown on the ADA Signage Installation Diagram page. | C34: 88 | D34: ='Rate Catalog'!H10 -> 50 | E34: =C34*D34 -> 4400 | F34: Confirmed
A35: Subtotal — Egress & Life Safety Signage | E35: =SUM(E32:E34) -> 11920
A37: GRAND TOTAL (Priced Items Only) | E37: =E10+E14+E29+E35 -> 27525
A39: Design, Installation & Sales Tax
A40: Design & Layout / File Setup | B40: Project file setup, layout, and artwork preparation across 18 sign types spanning Cellar through Roof (11 levels, 2 connected buildings). | C40: 1 | D40: 800 | E40: =C40*D40 -> 800 | F40: Estimated
A41: Installation Labor | B41: Installation labor, priced per crew-hour across all 496 signs, Cellar through Roof. Lift rental, electrical work, and permits excluded (customer to provide/hire separately). | C41: 2 | D41: 2800 | E41: =C41*D41 -> 5600 | F41: Estimated
E42: =E37+E40+E41 -> 33925
A43: Sales Tax Rate | E43: 0.08875
A44: Sales Tax | E44: =E42*E43 -> 3010.8438
A45: TOTAL INVESTMENT | E45: =E42+E44 -> 36935.844

Sheet Estimating Sheet
B1: 234 CLARKSON AVE.
B2: BROOKLYN, NY 11222
B3: SIGNAGES QUANTITY TAKEOFF
B4: Division 10 – Specialties | Section 10 14 00 – Signage
B5: Name | C5: Description | D5: Qty | E5: Units | F5: Cost Each | G5: Markup % | H5: Price Each | I5: Price Total | L5: QUANTITY SUMMARY | N5: Qty
B6: Exterior & Building Identification | L6: Exterior & Building Identification
B7: Building ID | D7: 1 | E7: EA | F7: =IFERROR(IF(ISNUMBER(INDEX('Signage Schedule'!$D:$D,MATCH(B7,'Signage Schedule'!$A:$A,0))),INDEX('Signage Schedule'!$D:$D,MATCH(B7,'Signage Schedule'!$A:$A,0)),0),0) -> 100 | I7: =D7*F7 -> 100 | L7: Building ID | N7: =SUMIF(B:B,L7,D:D) -> 1
B8: Standpipe / FDC Identification Sign (Assumed) | D8: 1 | E8: EA | F8: =IFERROR(IF(ISNUMBER(INDEX('Signage Schedule'!$D:$D,MATCH(B8,'Signage Schedule'!$A:$A,0))),INDEX('Signage Schedule'!$D:$D,MATCH(B8,'Signage Schedule'!$A:$A,0)),0),0) -> 25 | I8: =D8*F8 -> 25 | L8: Standpipe / FDC Identification Sign (Assumed) | N8: =SUMIF(B:B,L8,D:D) -> 1
B9: Cellar Level | I9: =D9*F9 -> 0 | L9: Site & Roadway Signage
B10: Interior Signage | I10: =D10*F10 -> 0 | L10: ADA Accessible Parking | N10: =SUMIF(B:B,L10,D:D) -> 1
B11: Elevator Evacuation Map | D11: 1 | E11: EA | F11: =IFERROR(IF(ISNUMBER(INDEX('Signage Schedule'!$D:$D,MATCH(B11,'Signage Schedule'!$A:$A,0))),INDEX('Signage Schedule'!$D:$D,MATCH(B11,'Signage Schedule'!$A:$A,0)),0),0) -> 85 | I11: =D11*F11 -> 85 | L11: Interior Signage
B12: Elevator Door Jamb Floor ID Sign | D12: 1 | E12: EA | F12: =IFERROR(IF(ISNUMBER(INDEX('Signage Schedule'!$D:$D,MATCH(B12,'Signage Schedule'!$A:$A,0))),INDEX('Signage Schedule'!$D:$D,MATCH(B12,'Signage Schedule'!$A:$A,0)),0),0) -> 45 | I12: =D12*F12 -> 45 | L12: Elevator Evacuation Map | N12: =SUMIF(B:B,L12,D:D) -> 22
B13: Elevator Lobby Floor Directory Signage | D13: 2 | E13: EA | F13: =IFERROR(IF(ISNUMBER(INDEX('Signage Schedule'!$D:$D,MATCH(B13,'Signage Schedule'!$A:$A,0))),INDEX('Signage Schedule'!$D:$D,MATCH(B13,'Signage Schedule'!$A:$A,0)),0),0) -> 50 | I13: =D13*F13 -> 100 | L13: Elevator Door Jamb Floor ID Sign | N13: =SUMIF(B:B,L13,D:D) -> 22
B14: Utility & Back-of-House ID Sign (w/ Hazard/Resticted-Access Signage) | D14: 5 | E14: EA | F14: =IFERROR(IF(ISNUMBER(INDEX('Signage Schedule'!$D:$D,MATCH(B14,'Signage Schedule'!$A:$A,0))),INDEX('Signage Schedule'!$D:$D,MATCH(B14,'Signage Schedule'!$A:$A,0)),0),0) -> 50 | I14: =D14*F14 -> 250 | L14: Elevator Lobby Floor Directory Signage | N14: =SUMIF(B:B,L14,D:D) -> 23
B15: Egress & Life Safety Signage | I15: =D15*F15 -> 0 | L15: Utility & Back-of-House ID Sign (w/ Hazard/Resticted-Access Signage) | N15: =SUMIF(B:B,L15,D:D) -> 27
B16: Illuminated EXIT Signage | D16: 2 | E16: EA | F16: =IFERROR(IF(ISNUMBER(INDEX('Signage Schedule'!$D:$D,MATCH(B16,'Signage Schedule'!$A:$A,0))),INDEX('Signage Schedule'!$D:$D,MATCH(B16,'Signage Schedule'!$A:$A,0)),0),0) -> 50 | I16: =D16*F16 -> 100 | L16: Utility & Back-of-House ID Sign | N16: =SUMIF(B:B,L16,D:D) -> 26
B17: Stairwell Floor-Level ID Plaque | D17: 2 | E17: EA | F17: =IFERROR(IF(ISNUMBER(INDEX('Signage Schedule'!$D:$D,MATCH(B17,'Signage Schedule'!$A:$A,0))),INDEX('Signage Schedule'!$D:$D,MATCH(B17,'Signage Schedule'!$A:$A,0)),0),0) -> 85 | I17: =D17*F17 -> 170 | L17: Typical Hallway Directory Signage | N17: =SUMIF(B:B,L17,D:D) -> 21
B18: Tactile/Braille Stair Door ID | D18: 4 | E18: EA | F18: =IFERROR(IF(ISNUMBER(INDEX('Signage Schedule'!$D:$D,MATCH(B18,'Signage Schedule'!$A:$A,0))),INDEX('Signage Schedule'!$D:$D,MATCH(B18,'Signage Schedule'!$A:$A,0)),0),0) -> 50 | I18: =D18*F18 -> 200 | L18: Lobby Floor Indicator Sign | N18: =SUMIF(B:B,L18,D:D) -> 1
B19: 1st Floor | I19: =D19*F19 -> 0 | L19: Amenity Room ID Signage | N19: =SUMIF(B:B,L19,D:D) -> 13
B20: Site & Roadway Signage | I20: =D20*F20 -> 0 | L20: Laundry Signage ("Loads of Fun") | N20: =SUMIF(B:B,L20,D:D) -> 1
B21: ADA Accessible Parking | D21: 1 | E21: EA | F21: =IFERROR(IF(ISNUMBER(INDEX('Signage Schedule'!$D:$D,MATCH(B21,'Signage Schedule'!$A:$A,0))),INDEX('Signage Schedule'!$D:$D,MATCH(B21,'Signage Schedule'!$A:$A,0)),0),0) -> 50 | I21: =D21*F21 -> 50 | L21: Co-Working Private Pod Signage | N21: =SUMIF(B:B,L21,D:D) -> 3
B22: Interior Signage | I22: =D22*F22 -> 0 | L22: Apartment Entry Signage | N22: =SUMIF(B:B,L22,D:D) -> 98
B23: Elevator Door Jamb Floor ID Sign | D23: 2 | E23: EA | F23: =IFERROR(IF(ISNUMBER(INDEX('Signage Schedule'!$D:$D,MATCH(B23,'Signage Schedule'!$A:$A,0))),INDEX('Signage Schedule'!$D:$D,MATCH(B23,'Signage Schedule'!$A:$A,0)),0),0) -> 45 | I23: =D23*F23 -> 90 | L23: Hazard/Restricted Access Signage | N23: =SUMIF(B:B,L23,D:D) -> 27
B24: Elevator Evacuation Map | D24: 2 | E24: EA | F24: =IFERROR(IF(ISNUMBER(INDEX('Signage Schedule'!$D:$D,MATCH(B24,'Signage Schedule'!$A:$A,0))),INDEX('Signage Schedule'!$D:$D,MATCH(B24,'Signage Schedule'!$A:$A,0)),0),0) -> 85 | I24: =D24*F24 -> 170 | L24: Egress & Life Safety Signage
B25: Utility & Back-of-House ID Sign | D25: 1 | E25: EA | F25: =IFERROR(IF(ISNUMBER(INDEX('Signage Schedule'!$D:$D,MATCH(B25,'Signage Schedule'!$A:$A,0))),INDEX('Signage Schedule'!$D:$D,MATCH(B25,'Signage Schedule'!$A:$A,0)),0),0) -> 50 | I25: =D25*F25 -> 50 | L25: Illuminated EXIT Signage | N25: =SUMIF(B:B,L25,D:D) -> 79
B26: Elevator Lobby Floor Directory Signage | D26: 2 | E26: EA | F26: =IFERROR(IF(ISNUMBER(INDEX('Signage Schedule'!$D:$D,MATCH(B26,'Signage Schedule'!$A:$A,0))),INDEX('Signage Schedule'!$D:$D,MATCH(B26,'Signage Schedule'!$A:$A,0)),0),0) -> 50 | I26: =D26*F26 -> 100 | L26: Stairwell Floor-Level ID Plaque | N26: =SUMIF(B:B,L26,D:D) -> 42
B27: Typical Hallway Directory Signage | D27: 2 | E27: EA | F27: =IFERROR(IF(ISNUMBER(INDEX('Signage Schedule'!$D:$D,MATCH(B27,'Signage Schedule'!$A:$A,0))),INDEX('Signage Schedule'!$D:$D,MATCH(B27,'Signage Schedule'!$A:$A,0)),0),0) -> 30 | I27: =D27*F27 -> 60 | L27: Tactile/Braille Stair Door ID | N27: =SUMIF(B:B,L27,D:D) -> 88
B28: Lobby Floor Indicator Sign | D28: 1 | E28: EA | F28: =IFERROR(IF(ISNUMBER(INDEX('Signage Schedule'!$D:$D,MATCH(B28,'Signage Schedule'!$A:$A,0))),INDEX('Signage Schedule'!$D:$D,MATCH(B28,'Signage Schedule'!$A:$A,0)),0),0) -> 50 | I28: =D28*F28 -> 50
B29: Amenity Room ID Signage | D29: 10 | E29: EA | F29: =IFERROR(IF(ISNUMBER(INDEX('Signage Schedule'!$D:$D,MATCH(B29,'Signage Schedule'!$A:$A,0))),INDEX('Signage Schedule'!$D:$D,MATCH(B29,'Signage Schedule'!$A:$A,0)),0),0) -> 50 | I29: =D29*F29 -> 500
B30: Laundry Signage ("Loads of Fun") | D30: 1 | E30: EA | F30: =IFERROR(IF(ISNUMBER(INDEX('Signage Schedule'!$D:$D,MATCH(B30,'Signage Schedule'!$A:$A,0))),INDEX('Signage Schedule'!$D:$D,MATCH(B30,'Signage Schedule'!$A:$A,0)),0),0) -> 400 | I30: =D30*F30 -> 400
B31: Co-Working Private Pod Signage | D31: 3 | E31: EA | F31: =IFERROR(IF(ISNUMBER(INDEX('Signage Schedule'!$D:$D,MATCH(B31,'Signage Schedule'!$A:$A,0))),INDEX('Signage Schedule'!$D:$D,MATCH(B31,'Signage Schedule'!$A:$A,0)),0),0) -> 50 | I31: =D31*F31 -> 150
B32: Utility & Back-of-House ID Sign (w/ Hazard/Resticted-Access Signage) | D32: 3 | E32: EA | F32: =IFERROR(IF(ISNUMBER(INDEX('Signage Schedule'!$D:$D,MATCH(B32,'Signage Schedule'!$A:$A,0))),INDEX('Signage Schedule'!$D:$D,MATCH(B32,'Signage Schedule'!$A:$A,0)),0),0) -> 50 | I32: =D32*F32 -> 150
B33: Egress & Life Safety Signage | I33: =D33*F33 -> 0
B34: Illuminated EXIT Signage | D34: 13 | E34: EA | F34: =IFERROR(IF(ISNUMBER(INDEX('Signage Schedule'!$D:$D,MATCH(B34,'Signage Schedule'!$A:$A,0))),INDEX('Signage Schedule'!$D:$D,MATCH(B34,'Signage Schedule'!$A:$A,0)),0),0) -> 50 | I34: =D34*F34 -> 650
B35: Stairwell Floor-Level ID Plaque | D35: 2 | E35: EA | F35: =IFERROR(IF(ISNUMBER(INDEX('Signage Schedule'!$D:$D,MATCH(B35,'Signage Schedule'!$A:$A,0))),INDEX('Signage Schedule'!$D:$D,MATCH(B35,'Signage Schedule'!$A:$A,0)),0),0) -> 85 | I35: =D35*F35 -> 170
B36: Tactile/Braille Stair Door ID | D36: 8 | E36: EA | F36: =IFERROR(IF(ISNUMBER(INDEX('Signage Schedule'!$D:$D,MATCH(B36,'Signage Schedule'!$A:$A,0))),INDEX('Signage Schedule'!$D:$D,MATCH(B36,'Signage Schedule'!$A:$A,0)),0),0) -> 50 | I36: =D36*F36 -> 400
B37: 2nd Floor
B38: Interior Signage
B39: Amenity Room ID Signage | D39: 3 | E39: EA | F39: =IFERROR(IF(ISNUMBER(INDEX('Signage Schedule'!$D:$D,MATCH(B39,'Signage Schedule'!$A:$A,0))),INDEX('Signage Schedule'!$D:$D,MATCH(B39,'Signage Schedule'!$A:$A,0)),0),0) -> 50 | I39: =D39*F39 -> 150
B40: Apartment Entry Signage | D40: 9 | E40: EA | F40: =IFERROR(IF(ISNUMBER(INDEX('Signage Schedule'!$D:$D,MATCH(B40,'Signage Schedule'!$A:$A,0))),INDEX('Signage Schedule'!$D:$D,MATCH(B40,'Signage Schedule'!$A:$A,0)),0),0) -> 60 | I40: =D40*F40 -> 540
...

Sheet Rate Catalog
A1: Item ID | B1: Category | C1: Sign Type | D1: Standard Size | E1: Material / Construction | F1: Pricing Method | G1: Unit | H1: Unit Price | I1: Minimum Price | J1: Calculation Rule | K1: Active | L1: Notes | M1: Source Project / Vendor Quote Ref | N1: Price Date | O1: Install Included? (Y/N) | P1: Confirmed-for-Project? (Y/N) | Q1: Quantity Break Pricing | R1: Lead Time | S1: Code Reference | T1: Freight / Delivery
A2: exterior-3d-pvc-letter-large | B2: Exterior & Building Identification | C2: Large 3D PVC Lettering - Painted by Code | D2: Over 20 to 30 high | E2: Exterior-grade PVC dimensional lettering, painted by code | F2: Per Letter | G2: Letter | H2: 100 | I2: 0 | J2: Character count x $100 | K2: =TRUE() -> TRUE | L2: Sourced from the B Visible Bid Signage Pricing catalog (219 Harman St. project). Non-lighted, individually mounted exterior-grade PVC lettering; painted by code. | CLARKSON APPLICATION: Client-confirmed height: 2 ft (24"). At 24", this falls in the catalog's Large 3D PVC Lettering tier (over 20–30") at $100/letter — not the Small tier ($50/letter) originally assumed. 3 characters (“234”) × $100 = $300. Moved from Estimated to Confirmed: the pricing tier is now a direct catalog match on a real client-supplied dimension, though exact finish/mounting still has no source detail sheet. | M2: 219 Harman St. — B Visible Bid Signage Pricing catalog | N2: Unknown (not dated in source catalog) | O2: N | P2: N — not vendor-quoted for 234 Clarkson Ave | Q2: Not published in source catalog (flat-rate assumed at all quantities) | R2: Not published in source catalog | S2: — | T2: Not published — assume local delivery included
A3: fdc-sign | B3: Site & Roadway | C3: FDC Sign | D3: Standard | E3: Printed rigid panel | F3: Fixed | G3: Each | H3: 25 | I3: 0 | J3: Qty x $25 | K3: =TRUE() -> TRUE | L3: Sourced from the B Visible Bid Signage Pricing catalog. Production only. | CLARKSON APPLICATION: Not in the Durukan Division 10 package — per Fire Protection General Note #2, priced against the standard FDC Sign rate. | M3: 219 Harman St. — B Visible Bid Signage Pricing catalog | N3: Unknown (not dated in source catalog) | O3: N | P3: N — not vendor-quoted for 234 Clarkson Ave | Q3: Not published in source catalog (flat-rate assumed at all quantities) | R3: Not published in source catalog | S3: NYC FC §912.4 / NFPA 14 | T3: Not published — assume local delivery included
A4: derived-evacuation-map | B4: Interior Signage | C4: Elevator Evacuation Map (Derived) | D4: 10 x 12 | E4: Printed/laminated panel, framed | F4: Fixed | G4: Each | H4: 85 | I4: 0 | J4: Qty x $85 | K4: =TRUE() -> TRUE | L4: Sourced from the B Visible catalog's own ESTIMATOR-DERIVED row — anchored to their Stairwell Interior ID Sign ($85), the closest real comparable (multi-content, floor-specific life-safety plaque). | CLARKSON APPLICATION: Not detailed in the Durukan package — priced via the catalog's own derived Evacuation Map rate. | M4: 219 Harman St. — B Visible Bid Signage Pricing catalog | N4: Unknown (not dated in source catalog) | O4: N | P4: N — not vendor-quoted for 234 Clarkson Ave | Q4: Not published in source catalog (flat-rate assumed at all quantities) | R4: Not published in source catalog | S4: — (fire-safety plan convention, R-2 occ.) | T4: Not published — assume local delivery included
A5: elevator-jamb-floor-id | B5: Interior Signage | C5: Elevator Door Jamb Floor ID | D5: Standard | E5: Raised characters and Braille | F5: Fixed | G5: Each | H5: 45 | I5: 0 | J5: Qty x $45 | K5: =TRUE() -> TRUE | L5: Sourced from the B Visible Bid Signage Pricing catalog. | CLARKSON APPLICATION: Not detailed in the Durukan package — direct catalog match on scope and format. | M5: 219 Harman St. — B Visible Bid Signage Pricing catalog | N5: Unknown (not dated in source catalog) | O5: N | P5: N — not vendor-quoted for 234 Clarkson Ave | Q5: Not published in source catalog (flat-rate assumed at all quantities) | R5: Not published in source catalog | S5: ASME A17.1 / NYC BC (elevator accessibility) | T5: Not published — assume local delivery included
A6: derived-floor-directory-a | B6: Interior Signage | C6: Floor Directory Signage A (Derived) | D6: Standard | E6: Acrylic plaque | F6: Fixed | G6: Each | H6: 50 | I6: 0 | J6: Qty x $50 | K6: =TRUE() -> TRUE | L6: Sourced from the B Visible catalog's own ESTIMATOR-DERIVED row — anchored to their Facility ID Sign ($50), same size/format tier (single dominant graphic element on a standard plaque). | CLARKSON APPLICATION: Per Durukan “Elevator Lobby Floor Directory Signage” detail (satin-nickel cutout metal, floor number + directory text + arrows) — priced via the catalog's derived Floor Directory A rate as the closest comparable dominant-numeral plaque. | M6: 219 Harman St. — B Visible Bid Signage Pricing catalog | N6: Unknown (not dated in source catalog) | O6: N | P6: N — not vendor-quoted for 234 Clarkson Ave | Q6: Not published in source catalog (flat-rate assumed at all quantities) | R6: Not published in source catalog | S6: — | T6: Not published — assume local delivery included
A7: utility-back-house-id | B7: Interior Signage | C7: Utility & Back-of-House ID Sign | D7: Standard ADA | E7: Raised characters and Braille | F7: Fixed | G7: Each | H7: 50 | I7: 0 | J7: Qty x $50 | K7: =TRUE() -> TRUE | L7: Sourced from the B Visible Bid Signage Pricing catalog. Standard non-fancy ADA plaque. | CLARKSON APPLICATION: No combined ID + hazard product in the catalog — priced at the base Utility & Back-of-House ID rate, same treatment as the Harman St. reference. | M7: 219 Harman St. — B Visible Bid Signage Pricing catalog | N7: Unknown (not dated in source catalog) | O7: N | P7: N — not vendor-quoted for 234 Clarkson Ave | Q7: Not published in source catalog (flat-rate assumed at all quantities) | R7: Not published in source catalog | S7: — | T7: Not published — assume local delivery included
A8: tactile-exit | B8: Egress & Life Safety | C8: Tactile EXIT Sign | D8: Standard ADA | E8: Raised letters and Braille | F8: Fixed | G8: Each | H8: 50 | I8: 0 | J8: Qty x $50 | K8: =TRUE() -> TRUE | L8: Sourced from the B Visible Bid Signage Pricing catalog. Small wall-mounted EXIT sign. | CLARKSON APPLICATION: Building height of 105'-0" places this within NYC high-rise egress-marking thresholds. Priced here as the catalog's Tactile EXIT Sign (non-illuminated ADA plaque) — if an electrically illuminated fixture is also required, that is Electrical-trade scope, excluded from this signage estimate. | M8: 219 Harman St. — B Visible Bid Signage Pricing catalog | N8: Unknown (not dated in source catalog) | O8: N | P8: N — not vendor-quoted for 234 Clarkson Ave | Q8: Not published in source catalog (flat-rate assumed at all quantities) | R8: Not published in source catalog | S8: NYC BC §1013 / §1013.4 | T8: Not published — assume local delivery included
A9: stairwell-interior-id | B9: Egress & Life Safety | C9: Stairwell Interior ID Sign | D9: 12 x 18 | E9: Multi-line sign with Braille | F9: Fixed | G9: Each | H9: 85 | I9: 0 | J9: Qty x $85 | K9: =TRUE() -> TRUE | L9: Sourced from the B Visible Bid Signage Pricing catalog. Includes floor, stair designation, floors served, and roof access copy. | CLARKSON APPLICATION: Direct catalog match — multi-line stairway ID plaque with floor/stair designation and roof-access copy. | M9: 219 Harman St. — B Visible Bid Signage Pricing catalog | N9: Unknown (not dated in source catalog) | O9: N | P9: N — not vendor-quoted for 234 Clarkson Ave | Q9: Not published in source catalog (flat-rate assumed at all quantities) | R9: Not published in source catalog | S9: NYC BC §1023.9 | T9: Not published — assume local delivery included
A10: tactile-exit | B10: Egress & Life Safety | C10: Tactile EXIT Sign | D10: Standard ADA | E10: Raised letters and Braille | F10: Fixed | G10: Each | H10: 50 | I10: 0 | J10: Qty x $50 | K10: =TRUE() -> TRUE | L10: Sourced from the B Visible Bid Signage Pricing catalog. Small wall-mounted EXIT sign. | CLARKSON APPLICATION: Direct catalog match to the Tactile EXIT Sign rate — same small ADA tactile format. | M10: 219 Harman St. — B Visible Bid Signage Pricing catalog | N10: Unknown (not dated in source catalog) | O10: N | P10: N — not vendor-quoted for 234 Clarkson Ave | Q10: Not published in source catalog (flat-rate assumed at all quantities) | R10: Not published in source catalog | S10: NYC BC §1013 / §1013.4 | T10: Not published — assume local delivery included
A11: ada-parking-12x18 | B11: Site & Roadway | C11: ADA Accessible Parking Sign | D11: 12 x 18 | E11: HIP reflective aluminum panel | F11: Fixed | G11: Each | H11: 50 | I11: 0 | J11: Qty x $50 | K11: =TRUE() -> TRUE | L11: Sourced from the B Visible Bid Signage Pricing catalog. Standard 12 x 18 HIP reflective sign. | CLARKSON APPLICATION: Direct catalog match. Post- vs. wall-mounted condition pending Site/Civil drawings (not included in this set). | M11: 219 Harman St. — B Visible Bid Signage Pricing catalog | N11: Unknown (not dated in source catalog) | O11: N | P11: N — not vendor-quoted for 234 Clarkson Ave | Q11: Not published in source catalog (flat-rate assumed at all quantities) | R11: Not published in source catalog | S11: ICC A117.1 / ADA parking signage | T11: Not published — assume local delivery included
A12: utility-back-house-id | B12: Interior Signage | C12: Utility & Back-of-House ID Sign | D12: Standard ADA | E12: Raised characters and Braille | F12: Fixed | G12: Each | H12: 50 | I12: 0 | J12: Qty x $50 | K12: =TRUE() -> TRUE | L12: Sourced from the B Visible Bid Signage Pricing catalog. Standard non-fancy ADA plaque. | CLARKSON APPLICATION: Direct catalog match — standard back-of-house room ID plaque. | M12: 219 Harman St. — B Visible Bid Signage Pricing catalog | N12: Unknown (not dated in source catalog) | O12: N | P12: N — not vendor-quoted for 234 Clarkson Ave | Q12: Not published in source catalog (flat-rate assumed at all quantities) | R12: Not published in source catalog | S12: — | T12: Not published — assume local delivery included
A13: derived-floor-directory-b | B13: Interior Signage | C13: Floor Directory Signage B (Derived) | D13: Standard | E13: Acrylic plaque | F13: Fixed | G13: Each | H13: 30 | I13: 0 | J13: Qty x $30 | K13: =TRUE() -> TRUE | L13: Sourced from the B Visible catalog's own ESTIMATOR-DERIVED row — anchored to an ACTUAL invoiced rate for “Wayfaring EXIT Signs” (directional arrow + text) on a real B Visible estimate: $30 each. | CLARKSON APPLICATION: Per Durukan “Typical Hallway Directory Signage” detail (unit-range + arrows) — priced via the catalog's derived Floor Directory B rate, same directional-wayfinding format. | M13: 219 Harman St. — B Visible Bid Signage Pricing catalog | N13: Unknown (not dated in source catalog) | O13: N | P13: N — not vendor-quoted for 234 Clarkson Ave | Q13: Not published in source catalog (flat-rate assumed at all quantities) | R13: Not published in source catalog | S13: — | T13: Not published — assume local delivery included
... A19: red-letter-utility-fire-room | B19: Egress & Life Safety | C19: Red-Lettered Utility / Fire Room Sign | D19: Standard | E19: Printed rigid panel | F19: Fixed | G19: Each | H19: 30 | I19: 0 | J19: Qty x $30 | K19: =TRUE() -> TRUE | L19: Sourced from the B Visible Bid Signage Pricing catalog. White panel with red identification copy. | CLARKSON APPLICATION: Not detailed in the Durukan package — priced against the closest real comparable, the Red-Lettered Utility/Fire Room Sign. | M19: 219 Harman St. — B Visible Bid Signage Pricing catalog | N19: Unknown (not dated in source catalog) | O19: N | P19: N — not vendor-quoted for 234 Clarkson Ave | Q19: Not published in source catalog (flat-rate assumed at all quantities) | R19: Not published in source catalog | S19: NYC BC §1010.1.9.4 | T19: Not published — assume local delivery included
